2025-03-16 14:45:28,909 - INFO - Received code comparison request
2025-03-16 14:45:28,910 - INFO - Generating reference solution
2025-03-16 14:45:30,835 - INFO - HTTP Request: POST https://api.openai.com/v1/chat/completions "HTTP/1.1 200 OK"
2025-03-16 14:45:30,847 - INFO - Comparing solutions
2025-03-16 14:45:43,389 - INFO - HTTP Request: POST https://api.openai.com/v1/chat/completions "HTTP/1.1 200 OK"
2025-03-16 14:45:43,392 - INFO - Generating report
2025-03-16 14:45:43,393 - INFO - Report generated at: reports/comparison_report_20250316_144543.md
2025-03-16 14:45:43,394 - ERROR - Error processing request: 2 validation errors for CodeComparisonResponse
similarity_score
  Field required [type=missing, input_value={'report_path': 'reports/...ort_20250316_144543.md'}, input_type=dict]
    For further information visit https://errors.pydantic.dev/2.10/v/missing
llm_solution
  Field required [type=missing, input_value={'report_path': 'reports/...ort_20250316_144543.md'}, input_type=dict]
    For further information visit https://errors.pydantic.dev/2.10/v/missing
Traceback (most recent call last):
  File "/Users/krishmakhijani/temp/TGBH_CheeseBurger/code-similarity/app/main_api.py", line 190, in compare_code
    return CodeComparisonResponse(
           ^^^^^^^^^^^^^^^^^^^^^^^
  File "/Users/krishmakhijani/.pyenv/versions/3.11.0/lib/python3.11/site-packages/pydantic/main.py", line 214, in __init__
    validated_self = self.__pydantic_validator__.validate_python(data, self_instance=self)
                     ^^^^^^^^^^^^^^^^^^^^^^^^^^^^^^^^^^^^^^^^^^^^^^^^^^^^^^^^^^^^^^^^^^^^^
pydantic_core._pydantic_core.ValidationError: 2 validation errors for CodeComparisonResponse
similarity_score
  Field required [type=missing, input_value={'report_path': 'reports/...ort_20250316_144543.md'}, input_type=dict]
    For further information visit https://errors.pydantic.dev/2.10/v/missing
llm_solution
  Field required [type=missing, input_value={'report_path': 'reports/...ort_20250316_144543.md'}, input_type=dict]
    For further information visit https://errors.pydantic.dev/2.10/v/missing
2025-03-16 14:45:43,398 - INFO - Received code comparison request
2025-03-16 14:45:43,398 - INFO - Generating reference solution
2025-03-16 14:45:44,772 - INFO - HTTP Request: POST https://api.openai.com/v1/chat/completions "HTTP/1.1 200 OK"
2025-03-16 14:45:44,776 - INFO - Comparing solutions
2025-03-16 14:46:00,301 - INFO - HTTP Request: POST https://api.openai.com/v1/chat/completions "HTTP/1.1 200 OK"
2025-03-16 14:46:00,305 - INFO - Generating report
2025-03-16 14:46:00,306 - INFO - Report generated at: reports/comparison_report_20250316_144600.md
2025-03-16 14:46:00,306 - ERROR - Error processing request: 2 validation errors for CodeComparisonResponse
similarity_score
  Field required [type=missing, input_value={'report_path': 'reports/...ort_20250316_144600.md'}, input_type=dict]
    For further information visit https://errors.pydantic.dev/2.10/v/missing
llm_solution
  Field required [type=missing, input_value={'report_path': 'reports/...ort_20250316_144600.md'}, input_type=dict]
    For further information visit https://errors.pydantic.dev/2.10/v/missing
Traceback (most recent call last):
  File "/Users/krishmakhijani/temp/TGBH_CheeseBurger/code-similarity/app/main_api.py", line 190, in compare_code
    return CodeComparisonResponse(
           ^^^^^^^^^^^^^^^^^^^^^^^
  File "/Users/krishmakhijani/.pyenv/versions/3.11.0/lib/python3.11/site-packages/pydantic/main.py", line 214, in __init__
    validated_self = self.__pydantic_validator__.validate_python(data, self_instance=self)
                     ^^^^^^^^^^^^^^^^^^^^^^^^^^^^^^^^^^^^^^^^^^^^^^^^^^^^^^^^^^^^^^^^^^^^^
pydantic_core._pydantic_core.ValidationError: 2 validation errors for CodeComparisonResponse
similarity_score
  Field required [type=missing, input_value={'report_path': 'reports/...ort_20250316_144600.md'}, input_type=dict]
    For further information visit https://errors.pydantic.dev/2.10/v/missing
llm_solution
  Field required [type=missing, input_value={'report_path': 'reports/...ort_20250316_144600.md'}, input_type=dict]
    For further information visit https://errors.pydantic.dev/2.10/v/missing
2025-03-16 14:47:56,064 - INFO - Received code comparison request
2025-03-16 14:47:56,065 - INFO - Generating reference solution
2025-03-16 14:47:59,428 - INFO - HTTP Request: POST https://api.openai.com/v1/chat/completions "HTTP/1.1 200 OK"
2025-03-16 14:47:59,430 - INFO - Comparing solutions
2025-03-16 14:48:08,150 - INFO - HTTP Request: POST https://api.openai.com/v1/chat/completions "HTTP/1.1 200 OK"
2025-03-16 14:48:08,153 - INFO - Generating report
2025-03-16 14:48:08,154 - INFO - Report generated at: reports/comparison_report_20250316_144808.md
2025-03-16 14:48:08,155 - ERROR - Error processing request: 2 validation errors for CodeComparisonResponse
similarity_score
  Field required [type=missing, input_value={'report_path': 'reports/...ort_20250316_144808.md'}, input_type=dict]
    For further information visit https://errors.pydantic.dev/2.10/v/missing
llm_solution
  Field required [type=missing, input_value={'report_path': 'reports/...ort_20250316_144808.md'}, input_type=dict]
    For further information visit https://errors.pydantic.dev/2.10/v/missing
Traceback (most recent call last):
  File "/Users/krishmakhijani/temp/TGBH_CheeseBurger/code-similarity/app/main_api.py", line 190, in compare_code
    similarity_score=similarity_score,
       ^^^^^^^^^^^^^^^^^^^^^^^^^^^^^^^
  File "/Users/krishmakhijani/.pyenv/versions/3.11.0/lib/python3.11/site-packages/pydantic/main.py", line 214, in __init__
    validated_self = self.__pydantic_validator__.validate_python(data, self_instance=self)
                     ^^^^^^^^^^^^^^^^^^^^^^^^^^^^^^^^^^^^^^^^^^^^^^^^^^^^^^^^^^^^^^^^^^^^^
pydantic_core._pydantic_core.ValidationError: 2 validation errors for CodeComparisonResponse
similarity_score
  Field required [type=missing, input_value={'report_path': 'reports/...ort_20250316_144808.md'}, input_type=dict]
    For further information visit https://errors.pydantic.dev/2.10/v/missing
llm_solution
  Field required [type=missing, input_value={'report_path': 'reports/...ort_20250316_144808.md'}, input_type=dict]
    For further information visit https://errors.pydantic.dev/2.10/v/missing
2025-03-16 14:48:13,386 - INFO - Received code comparison request
2025-03-16 14:48:13,387 - INFO - Generating reference solution
2025-03-16 14:48:14,827 - INFO - HTTP Request: POST https://api.openai.com/v1/chat/completions "HTTP/1.1 200 OK"
2025-03-16 14:48:14,849 - INFO - Comparing solutions
2025-03-16 14:48:28,497 - INFO - HTTP Request: POST https://api.openai.com/v1/chat/completions "HTTP/1.1 200 OK"
2025-03-16 14:48:28,502 - INFO - Generating report
2025-03-16 14:48:28,503 - INFO - Report generated at: reports/comparison_report_20250316_144828.md
2025-03-16 14:48:28,503 - ERROR - Error processing request: 2 validation errors for CodeComparisonResponse
similarity_score
  Field required [type=missing, input_value={'report_path': 'reports/...ort_20250316_144828.md'}, input_type=dict]
    For further information visit https://errors.pydantic.dev/2.10/v/missing
llm_solution
  Field required [type=missing, input_value={'report_path': 'reports/...ort_20250316_144828.md'}, input_type=dict]
    For further information visit https://errors.pydantic.dev/2.10/v/missing
Traceback (most recent call last):
  File "/Users/krishmakhijani/temp/TGBH_CheeseBurger/code-similarity/app/main_api.py", line 190, in compare_code
    similarity_score=similarity_score,
       ^^^^^^^^^^^^^^^^^^^^^^^^^^^^^^^
  File "/Users/krishmakhijani/.pyenv/versions/3.11.0/lib/python3.11/site-packages/pydantic/main.py", line 214, in __init__
    validated_self = self.__pydantic_validator__.validate_python(data, self_instance=self)
                     ^^^^^^^^^^^^^^^^^^^^^^^^^^^^^^^^^^^^^^^^^^^^^^^^^^^^^^^^^^^^^^^^^^^^^
pydantic_core._pydantic_core.ValidationError: 2 validation errors for CodeComparisonResponse
similarity_score
  Field required [type=missing, input_value={'report_path': 'reports/...ort_20250316_144828.md'}, input_type=dict]
    For further information visit https://errors.pydantic.dev/2.10/v/missing
llm_solution
  Field required [type=missing, input_value={'report_path': 'reports/...ort_20250316_144828.md'}, input_type=dict]
    For further information visit https://errors.pydantic.dev/2.10/v/missing
2025-03-16 14:48:35,213 - INFO - Received code comparison request
2025-03-16 14:48:35,214 - INFO - Generating reference solution
2025-03-16 14:48:36,843 - INFO - HTTP Request: POST https://api.openai.com/v1/chat/completions "HTTP/1.1 200 OK"
2025-03-16 14:48:36,845 - INFO - Comparing solutions
2025-03-16 14:48:45,397 - INFO - HTTP Request: POST https://api.openai.com/v1/chat/completions "HTTP/1.1 200 OK"
2025-03-16 14:48:45,405 - INFO - Generating report
2025-03-16 14:48:45,405 - INFO - Report generated at: reports/comparison_report_20250316_144845.md
2025-03-16 14:48:45,405 - ERROR - Error processing request: 2 validation errors for CodeComparisonResponse
similarity_score
  Field required [type=missing, input_value={'report_path': 'reports/...ort_20250316_144845.md'}, input_type=dict]
    For further information visit https://errors.pydantic.dev/2.10/v/missing
llm_solution
  Field required [type=missing, input_value={'report_path': 'reports/...ort_20250316_144845.md'}, input_type=dict]
    For further information visit https://errors.pydantic.dev/2.10/v/missing
Traceback (most recent call last):
  File "/Users/krishmakhijani/temp/TGBH_CheeseBurger/code-similarity/app/main_api.py", line 190, in compare_code
    similarity_score=similarity_score,
       ^^^^^^^^^^^^^^^^^^^^^^^^^^^^^^^
  File "/Users/krishmakhijani/.pyenv/versions/3.11.0/lib/python3.11/site-packages/pydantic/main.py", line 214, in __init__
    validated_self = self.__pydantic_validator__.validate_python(data, self_instance=self)
                     ^^^^^^^^^^^^^^^^^^^^^^^^^^^^^^^^^^^^^^^^^^^^^^^^^^^^^^^^^^^^^^^^^^^^^
pydantic_core._pydantic_core.ValidationError: 2 validation errors for CodeComparisonResponse
similarity_score
  Field required [type=missing, input_value={'report_path': 'reports/...ort_20250316_144845.md'}, input_type=dict]
    For further information visit https://errors.pydantic.dev/2.10/v/missing
llm_solution
  Field required [type=missing, input_value={'report_path': 'reports/...ort_20250316_144845.md'}, input_type=dict]
    For further information visit https://errors.pydantic.dev/2.10/v/missing
2025-03-16 14:48:45,511 - INFO - Received code comparison request
2025-03-16 14:48:45,511 - INFO - Generating reference solution
2025-03-16 14:48:46,851 - INFO - HTTP Request: POST https://api.openai.com/v1/chat/completions "HTTP/1.1 200 OK"
2025-03-16 14:48:46,855 - INFO - Comparing solutions
2025-03-16 14:48:53,889 - INFO - HTTP Request: POST https://api.openai.com/v1/chat/completions "HTTP/1.1 200 OK"
2025-03-16 14:48:53,903 - INFO - Generating report
2025-03-16 14:48:53,904 - INFO - Report generated at: reports/comparison_report_20250316_144853.md
2025-03-16 14:48:53,904 - ERROR - Error processing request: 2 validation errors for CodeComparisonResponse
similarity_score
  Field required [type=missing, input_value={'report_path': 'reports/...ort_20250316_144853.md'}, input_type=dict]
    For further information visit https://errors.pydantic.dev/2.10/v/missing
llm_solution
  Field required [type=missing, input_value={'report_path': 'reports/...ort_20250316_144853.md'}, input_type=dict]
    For further information visit https://errors.pydantic.dev/2.10/v/missing
Traceback (most recent call last):
  File "/Users/krishmakhijani/temp/TGBH_CheeseBurger/code-similarity/app/main_api.py", line 190, in compare_code
    similarity_score=similarity_score,
       ^^^^^^^^^^^^^^^^^^^^^^^^^^^^^^^
  File "/Users/krishmakhijani/.pyenv/versions/3.11.0/lib/python3.11/site-packages/pydantic/main.py", line 214, in __init__
    validated_self = self.__pydantic_validator__.validate_python(data, self_instance=self)
                     ^^^^^^^^^^^^^^^^^^^^^^^^^^^^^^^^^^^^^^^^^^^^^^^^^^^^^^^^^^^^^^^^^^^^^
pydantic_core._pydantic_core.ValidationError: 2 validation errors for CodeComparisonResponse
similarity_score
  Field required [type=missing, input_value={'report_path': 'reports/...ort_20250316_144853.md'}, input_type=dict]
    For further information visit https://errors.pydantic.dev/2.10/v/missing
llm_solution
  Field required [type=missing, input_value={'report_path': 'reports/...ort_20250316_144853.md'}, input_type=dict]
    For further information visit https://errors.pydantic.dev/2.10/v/missing
2025-03-16 14:48:55,235 - INFO - Received code comparison request
2025-03-16 14:48:55,235 - INFO - Generating reference solution
2025-03-16 14:48:56,872 - INFO - HTTP Request: POST https://api.openai.com/v1/chat/completions "HTTP/1.1 200 OK"
2025-03-16 14:48:56,879 - INFO - Comparing solutions
2025-03-16 14:49:04,722 - INFO - HTTP Request: POST https://api.openai.com/v1/chat/completions "HTTP/1.1 200 OK"
2025-03-16 14:49:04,731 - INFO - Generating report
2025-03-16 14:49:04,733 - INFO - Report generated at: reports/comparison_report_20250316_144904.md
2025-03-16 14:49:04,733 - ERROR - Error processing request: 2 validation errors for CodeComparisonResponse
similarity_score
  Field required [type=missing, input_value={'report_path': 'reports/...ort_20250316_144904.md'}, input_type=dict]
    For further information visit https://errors.pydantic.dev/2.10/v/missing
llm_solution
  Field required [type=missing, input_value={'report_path': 'reports/...ort_20250316_144904.md'}, input_type=dict]
    For further information visit https://errors.pydantic.dev/2.10/v/missing
Traceback (most recent call last):
  File "/Users/krishmakhijani/temp/TGBH_CheeseBurger/code-similarity/app/main_api.py", line 190, in compare_code
    similarity_score=similarity_score,
       ^^^^^^^^^^^^^^^^^^^^^^^^^^^^^^^
  File "/Users/krishmakhijani/.pyenv/versions/3.11.0/lib/python3.11/site-packages/pydantic/main.py", line 214, in __init__
    validated_self = self.__pydantic_validator__.validate_python(data, self_instance=self)
                     ^^^^^^^^^^^^^^^^^^^^^^^^^^^^^^^^^^^^^^^^^^^^^^^^^^^^^^^^^^^^^^^^^^^^^
pydantic_core._pydantic_core.ValidationError: 2 validation errors for CodeComparisonResponse
similarity_score
  Field required [type=missing, input_value={'report_path': 'reports/...ort_20250316_144904.md'}, input_type=dict]
    For further information visit https://errors.pydantic.dev/2.10/v/missing
llm_solution
  Field required [type=missing, input_value={'report_path': 'reports/...ort_20250316_144904.md'}, input_type=dict]
    For further information visit https://errors.pydantic.dev/2.10/v/missing
2025-03-16 14:50:45,804 - INFO - Received code comparison request
2025-03-16 14:50:45,804 - INFO - Generating reference solution
2025-03-16 14:50:47,524 - INFO - HTTP Request: POST https://api.openai.com/v1/chat/completions "HTTP/1.1 200 OK"
2025-03-16 14:50:47,534 - INFO - Comparing solutions
2025-03-16 14:50:56,885 - INFO - HTTP Request: POST https://api.openai.com/v1/chat/completions "HTTP/1.1 200 OK"
2025-03-16 14:50:56,888 - INFO - Generating report
2025-03-16 14:50:56,889 - INFO - Report generated at: reports/comparison_report_20250316_145056.md
2025-03-16 14:50:56,889 - ERROR - Error processing request: 2 validation errors for CodeComparisonResponse
similarity_score
  Field required [type=missing, input_value={'report_path': 'reports/...ort_20250316_145056.md'}, input_type=dict]
    For further information visit https://errors.pydantic.dev/2.10/v/missing
llm_solution
  Field required [type=missing, input_value={'report_path': 'reports/...ort_20250316_145056.md'}, input_type=dict]
    For further information visit https://errors.pydantic.dev/2.10/v/missing
Traceback (most recent call last):
  File "/Users/krishmakhijani/temp/TGBH_CheeseBurger/code-similarity/app/main_api.py", line 190, in compare_code
    report_path=report_path,
       ^^^^^^^^^^^^^^^^^^^^^
  File "/Users/krishmakhijani/.pyenv/versions/3.11.0/lib/python3.11/site-packages/pydantic/main.py", line 214, in __init__
    validated_self = self.__pydantic_validator__.validate_python(data, self_instance=self)
                     ^^^^^^^^^^^^^^^^^^^^^^^^^^^^^^^^^^^^^^^^^^^^^^^^^^^^^^^^^^^^^^^^^^^^^
pydantic_core._pydantic_core.ValidationError: 2 validation errors for CodeComparisonResponse
similarity_score
  Field required [type=missing, input_value={'report_path': 'reports/...ort_20250316_145056.md'}, input_type=dict]
    For further information visit https://errors.pydantic.dev/2.10/v/missing
llm_solution
  Field required [type=missing, input_value={'report_path': 'reports/...ort_20250316_145056.md'}, input_type=dict]
    For further information visit https://errors.pydantic.dev/2.10/v/missing
2025-03-16 14:52:18,927 - INFO - Received code comparison request
2025-03-16 14:52:18,928 - INFO - Generating reference solution
2025-03-16 14:52:21,542 - INFO - HTTP Request: POST https://api.openai.com/v1/chat/completions "HTTP/1.1 200 OK"
2025-03-16 14:52:21,547 - INFO - Comparing solutions
2025-03-16 14:52:30,503 - INFO - HTTP Request: POST https://api.openai.com/v1/chat/completions "HTTP/1.1 200 OK"
2025-03-16 14:52:30,507 - INFO - Generating report
2025-03-16 14:52:30,508 - INFO - Report generated at: reports/comparison_report_20250316_145230.md
2025-03-16 14:52:30,509 - ERROR - Error processing request: 2 validation errors for CodeComparisonResponse
similarity_score
  Field required [type=missing, input_value={'report_path': 'reports/...ort_20250316_145230.md'}, input_type=dict]
    For further information visit https://errors.pydantic.dev/2.10/v/missing
llm_solution
  Field required [type=missing, input_value={'report_path': 'reports/...ort_20250316_145230.md'}, input_type=dict]
    For further information visit https://errors.pydantic.dev/2.10/v/missing
Traceback (most recent call last):
  File "/Users/krishmakhijani/temp/TGBH_CheeseBurger/code-similarity/app/main_api.py", line 190, in compare_code
    report_path=report_path,
       ^^^^^^^^^^^^^^^^^^^^^
  File "/Users/krishmakhijani/.pyenv/versions/3.11.0/lib/python3.11/site-packages/pydantic/main.py", line 214, in __init__
    validated_self = self.__pydantic_validator__.validate_python(data, self_instance=self)
                     ^^^^^^^^^^^^^^^^^^^^^^^^^^^^^^^^^^^^^^^^^^^^^^^^^^^^^^^^^^^^^^^^^^^^^
pydantic_core._pydantic_core.ValidationError: 2 validation errors for CodeComparisonResponse
similarity_score
  Field required [type=missing, input_value={'report_path': 'reports/...ort_20250316_145230.md'}, input_type=dict]
    For further information visit https://errors.pydantic.dev/2.10/v/missing
llm_solution
  Field required [type=missing, input_value={'report_path': 'reports/...ort_20250316_145230.md'}, input_type=dict]
    For further information visit https://errors.pydantic.dev/2.10/v/missing
2025-03-16 14:54:00,440 - INFO - Received code comparison request
2025-03-16 14:54:00,441 - INFO - Generating reference solution
2025-03-16 14:54:02,236 - INFO - HTTP Request: POST https://api.openai.com/v1/chat/completions "HTTP/1.1 200 OK"
2025-03-16 14:54:02,239 - INFO - Comparing solutions
2025-03-16 14:54:11,768 - INFO - HTTP Request: POST https://api.openai.com/v1/chat/completions "HTTP/1.1 200 OK"
2025-03-16 14:54:11,771 - INFO - Generating report
2025-03-16 14:54:11,773 - INFO - Report generated at: reports/comparison_report_20250316_145411.md
2025-03-16 14:54:11,773 - ERROR - Error processing request: 2 validation errors for CodeComparisonResponse
similarity_score
  Field required [type=missing, input_value={'report_path': 'reports/...ort_20250316_145411.md'}, input_type=dict]
    For further information visit https://errors.pydantic.dev/2.10/v/missing
llm_solution
  Field required [type=missing, input_value={'report_path': 'reports/...ort_20250316_145411.md'}, input_type=dict]
    For further information visit https://errors.pydantic.dev/2.10/v/missing
Traceback (most recent call last):
  File "/Users/krishmakhijani/temp/TGBH_CheeseBurger/code-similarity/app/main_api.py", line 190, in compare_code
    report_path=report_path,
       ^^^^^^^^^^^^^^^^^^^^^
  File "/Users/krishmakhijani/.pyenv/versions/3.11.0/lib/python3.11/site-packages/pydantic/main.py", line 214, in __init__
    validated_self = self.__pydantic_validator__.validate_python(data, self_instance=self)
                     ^^^^^^^^^^^^^^^^^^^^^^^^^^^^^^^^^^^^^^^^^^^^^^^^^^^^^^^^^^^^^^^^^^^^^
pydantic_core._pydantic_core.ValidationError: 2 validation errors for CodeComparisonResponse
similarity_score
  Field required [type=missing, input_value={'report_path': 'reports/...ort_20250316_145411.md'}, input_type=dict]
    For further information visit https://errors.pydantic.dev/2.10/v/missing
llm_solution
  Field required [type=missing, input_value={'report_path': 'reports/...ort_20250316_145411.md'}, input_type=dict]
    For further information visit https://errors.pydantic.dev/2.10/v/missing
